[2024-10-16T11:29:49.559+0000] {processor.py:186} INFO - Started process (PID=125570) to work on /opt/airflow/dags/eleicao_dag.py
[2024-10-16T11:29:49.572+0000] {processor.py:914} INFO - Processing file /opt/airflow/dags/eleicao_dag.py for tasks to queue
[2024-10-16T11:29:49.590+0000] {logging_mixin.py:190} INFO - [2024-10-16T11:29:49.590+0000] {dagbag.py:588} INFO - Filling up the DagBag from /opt/airflow/dags/eleicao_dag.py
[2024-10-16T11:29:51.038+0000] {logging_mixin.py:190} INFO - [2024-10-16T11:29:50.930+0000] {dagbag.py:387} ERROR - Failed to import: /opt/airflow/dags/eleicao_dag.py
Traceback (most recent call last):
  File "/home/airflow/.local/lib/python3.12/site-packages/airflow/models/dagbag.py", line 383, in parse
    loader.exec_module(new_module)
  File "<frozen importlib._bootstrap_external>", line 995, in exec_module
  File "<frozen importlib._bootstrap>", line 488, in _call_with_frames_removed
  File "/opt/airflow/dags/eleicao_dag.py", line 234, in <module>
    python_callable=process_files,
                    ^^^^^^^^^^^^^
NameError: name 'process_files' is not defined. Did you mean: 'process_log_file'?
[2024-10-16T11:29:51.079+0000] {processor.py:927} WARNING - No viable dags retrieved from /opt/airflow/dags/eleicao_dag.py
[2024-10-16T11:29:51.317+0000] {processor.py:208} INFO - Processing /opt/airflow/dags/eleicao_dag.py took 1.832 seconds
[2024-10-16T11:30:22.050+0000] {processor.py:186} INFO - Started process (PID=125634) to work on /opt/airflow/dags/eleicao_dag.py
[2024-10-16T11:30:22.053+0000] {processor.py:914} INFO - Processing file /opt/airflow/dags/eleicao_dag.py for tasks to queue
[2024-10-16T11:30:22.054+0000] {logging_mixin.py:190} INFO - [2024-10-16T11:30:22.054+0000] {dagbag.py:588} INFO - Filling up the DagBag from /opt/airflow/dags/eleicao_dag.py
[2024-10-16T11:30:22.226+0000] {logging_mixin.py:190} INFO - [2024-10-16T11:30:22.216+0000] {dagbag.py:387} ERROR - Failed to import: /opt/airflow/dags/eleicao_dag.py
Traceback (most recent call last):
  File "/home/airflow/.local/lib/python3.12/site-packages/airflow/models/dagbag.py", line 383, in parse
    loader.exec_module(new_module)
  File "<frozen importlib._bootstrap_external>", line 995, in exec_module
  File "<frozen importlib._bootstrap>", line 488, in _call_with_frames_removed
  File "/opt/airflow/dags/eleicao_dag.py", line 234, in <module>
    python_callable=process_files,
                    ^^^^^^^^^^^^^
NameError: name 'process_files' is not defined. Did you mean: 'process_log_file'?
[2024-10-16T11:30:22.234+0000] {processor.py:927} WARNING - No viable dags retrieved from /opt/airflow/dags/eleicao_dag.py
[2024-10-16T11:30:22.253+0000] {processor.py:208} INFO - Processing /opt/airflow/dags/eleicao_dag.py took 0.212 seconds
[2024-10-16T11:30:53.227+0000] {processor.py:186} INFO - Started process (PID=125697) to work on /opt/airflow/dags/eleicao_dag.py
[2024-10-16T11:30:53.228+0000] {processor.py:914} INFO - Processing file /opt/airflow/dags/eleicao_dag.py for tasks to queue
[2024-10-16T11:30:53.230+0000] {logging_mixin.py:190} INFO - [2024-10-16T11:30:53.229+0000] {dagbag.py:588} INFO - Filling up the DagBag from /opt/airflow/dags/eleicao_dag.py
[2024-10-16T11:30:53.344+0000] {logging_mixin.py:190} INFO - [2024-10-16T11:30:53.336+0000] {dagbag.py:387} ERROR - Failed to import: /opt/airflow/dags/eleicao_dag.py
Traceback (most recent call last):
  File "/home/airflow/.local/lib/python3.12/site-packages/airflow/models/dagbag.py", line 383, in parse
    loader.exec_module(new_module)
  File "<frozen importlib._bootstrap_external>", line 995, in exec_module
  File "<frozen importlib._bootstrap>", line 488, in _call_with_frames_removed
  File "/opt/airflow/dags/eleicao_dag.py", line 234, in <module>
    python_callable=process_files,
                    ^^^^^^^^^^^^^
NameError: name 'process_files' is not defined. Did you mean: 'process_log_file'?
[2024-10-16T11:30:53.349+0000] {processor.py:927} WARNING - No viable dags retrieved from /opt/airflow/dags/eleicao_dag.py
[2024-10-16T11:30:53.366+0000] {processor.py:208} INFO - Processing /opt/airflow/dags/eleicao_dag.py took 0.145 seconds
[2024-10-16T11:31:24.027+0000] {processor.py:186} INFO - Started process (PID=125760) to work on /opt/airflow/dags/eleicao_dag.py
[2024-10-16T11:31:24.027+0000] {processor.py:914} INFO - Processing file /opt/airflow/dags/eleicao_dag.py for tasks to queue
[2024-10-16T11:31:24.029+0000] {logging_mixin.py:190} INFO - [2024-10-16T11:31:24.028+0000] {dagbag.py:588} INFO - Filling up the DagBag from /opt/airflow/dags/eleicao_dag.py
[2024-10-16T11:31:24.145+0000] {logging_mixin.py:190} INFO - [2024-10-16T11:31:24.136+0000] {dagbag.py:387} ERROR - Failed to import: /opt/airflow/dags/eleicao_dag.py
Traceback (most recent call last):
  File "/home/airflow/.local/lib/python3.12/site-packages/airflow/models/dagbag.py", line 383, in parse
    loader.exec_module(new_module)
  File "<frozen importlib._bootstrap_external>", line 995, in exec_module
  File "<frozen importlib._bootstrap>", line 488, in _call_with_frames_removed
  File "/opt/airflow/dags/eleicao_dag.py", line 234, in <module>
    python_callable=process_files,
                    ^^^^^^^^^^^^^
NameError: name 'process_files' is not defined. Did you mean: 'process_log_file'?
[2024-10-16T11:31:24.150+0000] {processor.py:927} WARNING - No viable dags retrieved from /opt/airflow/dags/eleicao_dag.py
[2024-10-16T11:31:24.168+0000] {processor.py:208} INFO - Processing /opt/airflow/dags/eleicao_dag.py took 0.148 seconds
[2024-10-16T11:31:54.528+0000] {processor.py:186} INFO - Started process (PID=125823) to work on /opt/airflow/dags/eleicao_dag.py
[2024-10-16T11:31:54.529+0000] {processor.py:914} INFO - Processing file /opt/airflow/dags/eleicao_dag.py for tasks to queue
[2024-10-16T11:31:54.530+0000] {logging_mixin.py:190} INFO - [2024-10-16T11:31:54.530+0000] {dagbag.py:588} INFO - Filling up the DagBag from /opt/airflow/dags/eleicao_dag.py
[2024-10-16T11:31:54.647+0000] {logging_mixin.py:190} INFO - [2024-10-16T11:31:54.636+0000] {dagbag.py:387} ERROR - Failed to import: /opt/airflow/dags/eleicao_dag.py
Traceback (most recent call last):
  File "/home/airflow/.local/lib/python3.12/site-packages/airflow/models/dagbag.py", line 383, in parse
    loader.exec_module(new_module)
  File "<frozen importlib._bootstrap_external>", line 995, in exec_module
  File "<frozen importlib._bootstrap>", line 488, in _call_with_frames_removed
  File "/opt/airflow/dags/eleicao_dag.py", line 234, in <module>
    python_callable=process_files,
                    ^^^^^^^^^^^^^
NameError: name 'process_files' is not defined. Did you mean: 'process_log_file'?
[2024-10-16T11:31:54.652+0000] {processor.py:927} WARNING - No viable dags retrieved from /opt/airflow/dags/eleicao_dag.py
[2024-10-16T11:31:54.669+0000] {processor.py:208} INFO - Processing /opt/airflow/dags/eleicao_dag.py took 0.148 seconds
[2024-10-16T11:32:25.062+0000] {processor.py:186} INFO - Started process (PID=125886) to work on /opt/airflow/dags/eleicao_dag.py
[2024-10-16T11:32:25.063+0000] {processor.py:914} INFO - Processing file /opt/airflow/dags/eleicao_dag.py for tasks to queue
[2024-10-16T11:32:25.065+0000] {logging_mixin.py:190} INFO - [2024-10-16T11:32:25.064+0000] {dagbag.py:588} INFO - Filling up the DagBag from /opt/airflow/dags/eleicao_dag.py
[2024-10-16T11:32:25.173+0000] {logging_mixin.py:190} INFO - [2024-10-16T11:32:25.163+0000] {dagbag.py:387} ERROR - Failed to import: /opt/airflow/dags/eleicao_dag.py
Traceback (most recent call last):
  File "/home/airflow/.local/lib/python3.12/site-packages/airflow/models/dagbag.py", line 383, in parse
    loader.exec_module(new_module)
  File "<frozen importlib._bootstrap_external>", line 995, in exec_module
  File "<frozen importlib._bootstrap>", line 488, in _call_with_frames_removed
  File "/opt/airflow/dags/eleicao_dag.py", line 234, in <module>
    python_callable=process_files,
                    ^^^^^^^^^^^^^
NameError: name 'process_files' is not defined. Did you mean: 'process_log_file'?
[2024-10-16T11:32:25.179+0000] {processor.py:927} WARNING - No viable dags retrieved from /opt/airflow/dags/eleicao_dag.py
[2024-10-16T11:32:25.196+0000] {processor.py:208} INFO - Processing /opt/airflow/dags/eleicao_dag.py took 0.141 seconds
[2024-10-16T11:32:55.510+0000] {processor.py:186} INFO - Started process (PID=125949) to work on /opt/airflow/dags/eleicao_dag.py
[2024-10-16T11:32:55.511+0000] {processor.py:914} INFO - Processing file /opt/airflow/dags/eleicao_dag.py for tasks to queue
[2024-10-16T11:32:55.512+0000] {logging_mixin.py:190} INFO - [2024-10-16T11:32:55.512+0000] {dagbag.py:588} INFO - Filling up the DagBag from /opt/airflow/dags/eleicao_dag.py
[2024-10-16T11:32:55.632+0000] {logging_mixin.py:190} INFO - [2024-10-16T11:32:55.622+0000] {dagbag.py:387} ERROR - Failed to import: /opt/airflow/dags/eleicao_dag.py
Traceback (most recent call last):
  File "/home/airflow/.local/lib/python3.12/site-packages/airflow/models/dagbag.py", line 383, in parse
    loader.exec_module(new_module)
  File "<frozen importlib._bootstrap_external>", line 995, in exec_module
  File "<frozen importlib._bootstrap>", line 488, in _call_with_frames_removed
  File "/opt/airflow/dags/eleicao_dag.py", line 234, in <module>
    python_callable=process_files,
                    ^^^^^^^^^^^^^
NameError: name 'process_files' is not defined. Did you mean: 'process_log_file'?
[2024-10-16T11:32:55.637+0000] {processor.py:927} WARNING - No viable dags retrieved from /opt/airflow/dags/eleicao_dag.py
[2024-10-16T11:32:55.655+0000] {processor.py:208} INFO - Processing /opt/airflow/dags/eleicao_dag.py took 0.151 seconds
[2024-10-16T11:33:25.807+0000] {processor.py:186} INFO - Started process (PID=126012) to work on /opt/airflow/dags/eleicao_dag.py
[2024-10-16T11:33:25.807+0000] {processor.py:914} INFO - Processing file /opt/airflow/dags/eleicao_dag.py for tasks to queue
[2024-10-16T11:33:25.809+0000] {logging_mixin.py:190} INFO - [2024-10-16T11:33:25.809+0000] {dagbag.py:588} INFO - Filling up the DagBag from /opt/airflow/dags/eleicao_dag.py
[2024-10-16T11:33:25.934+0000] {logging_mixin.py:190} INFO - [2024-10-16T11:33:25.926+0000] {dagbag.py:387} ERROR - Failed to import: /opt/airflow/dags/eleicao_dag.py
Traceback (most recent call last):
  File "/home/airflow/.local/lib/python3.12/site-packages/airflow/models/dagbag.py", line 383, in parse
    loader.exec_module(new_module)
  File "<frozen importlib._bootstrap_external>", line 995, in exec_module
  File "<frozen importlib._bootstrap>", line 488, in _call_with_frames_removed
  File "/opt/airflow/dags/eleicao_dag.py", line 234, in <module>
    python_callable=process_files,
                    ^^^^^^^^^^^^^
NameError: name 'process_files' is not defined. Did you mean: 'process_log_file'?
[2024-10-16T11:33:25.939+0000] {processor.py:927} WARNING - No viable dags retrieved from /opt/airflow/dags/eleicao_dag.py
[2024-10-16T11:33:25.960+0000] {processor.py:208} INFO - Processing /opt/airflow/dags/eleicao_dag.py took 0.159 seconds
[2024-10-16T11:33:56.012+0000] {processor.py:186} INFO - Started process (PID=126075) to work on /opt/airflow/dags/eleicao_dag.py
[2024-10-16T11:33:56.013+0000] {processor.py:914} INFO - Processing file /opt/airflow/dags/eleicao_dag.py for tasks to queue
[2024-10-16T11:33:56.014+0000] {logging_mixin.py:190} INFO - [2024-10-16T11:33:56.014+0000] {dagbag.py:588} INFO - Filling up the DagBag from /opt/airflow/dags/eleicao_dag.py
[2024-10-16T11:33:56.133+0000] {logging_mixin.py:190} INFO - [2024-10-16T11:33:56.124+0000] {dagbag.py:387} ERROR - Failed to import: /opt/airflow/dags/eleicao_dag.py
Traceback (most recent call last):
  File "/home/airflow/.local/lib/python3.12/site-packages/airflow/models/dagbag.py", line 383, in parse
    loader.exec_module(new_module)
  File "<frozen importlib._bootstrap_external>", line 995, in exec_module
  File "<frozen importlib._bootstrap>", line 488, in _call_with_frames_removed
  File "/opt/airflow/dags/eleicao_dag.py", line 234, in <module>
    python_callable=process_files,
                    ^^^^^^^^^^^^^
NameError: name 'process_files' is not defined. Did you mean: 'process_log_file'?
[2024-10-16T11:33:56.139+0000] {processor.py:927} WARNING - No viable dags retrieved from /opt/airflow/dags/eleicao_dag.py
[2024-10-16T11:33:56.158+0000] {processor.py:208} INFO - Processing /opt/airflow/dags/eleicao_dag.py took 0.152 seconds
[2024-10-16T11:34:26.369+0000] {processor.py:186} INFO - Started process (PID=126139) to work on /opt/airflow/dags/eleicao_dag.py
[2024-10-16T11:34:26.370+0000] {processor.py:914} INFO - Processing file /opt/airflow/dags/eleicao_dag.py for tasks to queue
[2024-10-16T11:34:26.372+0000] {logging_mixin.py:190} INFO - [2024-10-16T11:34:26.372+0000] {dagbag.py:588} INFO - Filling up the DagBag from /opt/airflow/dags/eleicao_dag.py
[2024-10-16T11:34:26.550+0000] {logging_mixin.py:190} INFO - [2024-10-16T11:34:26.530+0000] {dagbag.py:387} ERROR - Failed to import: /opt/airflow/dags/eleicao_dag.py
Traceback (most recent call last):
  File "/home/airflow/.local/lib/python3.12/site-packages/airflow/models/dagbag.py", line 383, in parse
    loader.exec_module(new_module)
  File "<frozen importlib._bootstrap_external>", line 995, in exec_module
  File "<frozen importlib._bootstrap>", line 488, in _call_with_frames_removed
  File "/opt/airflow/dags/eleicao_dag.py", line 234, in <module>
    python_callable=process_files,
                    ^^^^^^^^^^^^^
NameError: name 'process_files' is not defined. Did you mean: 'process_log_file'?
[2024-10-16T11:34:26.558+0000] {processor.py:927} WARNING - No viable dags retrieved from /opt/airflow/dags/eleicao_dag.py
[2024-10-16T11:34:26.584+0000] {processor.py:208} INFO - Processing /opt/airflow/dags/eleicao_dag.py took 0.222 seconds
[2024-10-16T11:34:56.660+0000] {processor.py:186} INFO - Started process (PID=126203) to work on /opt/airflow/dags/eleicao_dag.py
[2024-10-16T11:34:56.661+0000] {processor.py:914} INFO - Processing file /opt/airflow/dags/eleicao_dag.py for tasks to queue
[2024-10-16T11:34:56.663+0000] {logging_mixin.py:190} INFO - [2024-10-16T11:34:56.662+0000] {dagbag.py:588} INFO - Filling up the DagBag from /opt/airflow/dags/eleicao_dag.py
[2024-10-16T11:34:56.769+0000] {logging_mixin.py:190} INFO - [2024-10-16T11:34:56.761+0000] {dagbag.py:387} ERROR - Failed to import: /opt/airflow/dags/eleicao_dag.py
Traceback (most recent call last):
  File "/home/airflow/.local/lib/python3.12/site-packages/airflow/models/dagbag.py", line 383, in parse
    loader.exec_module(new_module)
  File "<frozen importlib._bootstrap_external>", line 995, in exec_module
  File "<frozen importlib._bootstrap>", line 488, in _call_with_frames_removed
  File "/opt/airflow/dags/eleicao_dag.py", line 234, in <module>
    python_callable=process_files,
                    ^^^^^^^^^^^^^
NameError: name 'process_files' is not defined. Did you mean: 'process_log_file'?
[2024-10-16T11:34:56.774+0000] {processor.py:927} WARNING - No viable dags retrieved from /opt/airflow/dags/eleicao_dag.py
[2024-10-16T11:34:56.789+0000] {processor.py:208} INFO - Processing /opt/airflow/dags/eleicao_dag.py took 0.135 seconds
[2024-10-16T11:35:27.302+0000] {processor.py:186} INFO - Started process (PID=126265) to work on /opt/airflow/dags/eleicao_dag.py
[2024-10-16T11:35:27.304+0000] {processor.py:914} INFO - Processing file /opt/airflow/dags/eleicao_dag.py for tasks to queue
[2024-10-16T11:35:27.306+0000] {logging_mixin.py:190} INFO - [2024-10-16T11:35:27.305+0000] {dagbag.py:588} INFO - Filling up the DagBag from /opt/airflow/dags/eleicao_dag.py
[2024-10-16T11:35:27.423+0000] {logging_mixin.py:190} INFO - [2024-10-16T11:35:27.414+0000] {dagbag.py:387} ERROR - Failed to import: /opt/airflow/dags/eleicao_dag.py
Traceback (most recent call last):
  File "/home/airflow/.local/lib/python3.12/site-packages/airflow/models/dagbag.py", line 383, in parse
    loader.exec_module(new_module)
  File "<frozen importlib._bootstrap_external>", line 995, in exec_module
  File "<frozen importlib._bootstrap>", line 488, in _call_with_frames_removed
  File "/opt/airflow/dags/eleicao_dag.py", line 234, in <module>
    python_callable=process_files,
                    ^^^^^^^^^^^^^
NameError: name 'process_files' is not defined. Did you mean: 'process_log_file'?
[2024-10-16T11:35:27.428+0000] {processor.py:927} WARNING - No viable dags retrieved from /opt/airflow/dags/eleicao_dag.py
[2024-10-16T11:35:27.445+0000] {processor.py:208} INFO - Processing /opt/airflow/dags/eleicao_dag.py took 0.150 seconds
[2024-10-16T11:35:57.791+0000] {processor.py:186} INFO - Started process (PID=126328) to work on /opt/airflow/dags/eleicao_dag.py
[2024-10-16T11:35:57.792+0000] {processor.py:914} INFO - Processing file /opt/airflow/dags/eleicao_dag.py for tasks to queue
[2024-10-16T11:35:57.794+0000] {logging_mixin.py:190} INFO - [2024-10-16T11:35:57.793+0000] {dagbag.py:588} INFO - Filling up the DagBag from /opt/airflow/dags/eleicao_dag.py
[2024-10-16T11:35:57.903+0000] {logging_mixin.py:190} INFO - [2024-10-16T11:35:57.895+0000] {dagbag.py:387} ERROR - Failed to import: /opt/airflow/dags/eleicao_dag.py
Traceback (most recent call last):
  File "/home/airflow/.local/lib/python3.12/site-packages/airflow/models/dagbag.py", line 383, in parse
    loader.exec_module(new_module)
  File "<frozen importlib._bootstrap_external>", line 995, in exec_module
  File "<frozen importlib._bootstrap>", line 488, in _call_with_frames_removed
  File "/opt/airflow/dags/eleicao_dag.py", line 234, in <module>
    python_callable=process_files,
                    ^^^^^^^^^^^^^
NameError: name 'process_files' is not defined. Did you mean: 'process_log_file'?
[2024-10-16T11:35:57.909+0000] {processor.py:927} WARNING - No viable dags retrieved from /opt/airflow/dags/eleicao_dag.py
[2024-10-16T11:35:57.926+0000] {processor.py:208} INFO - Processing /opt/airflow/dags/eleicao_dag.py took 0.142 seconds
[2024-10-16T11:36:28.531+0000] {processor.py:186} INFO - Started process (PID=126392) to work on /opt/airflow/dags/eleicao_dag.py
[2024-10-16T11:36:28.532+0000] {processor.py:914} INFO - Processing file /opt/airflow/dags/eleicao_dag.py for tasks to queue
[2024-10-16T11:36:28.534+0000] {logging_mixin.py:190} INFO - [2024-10-16T11:36:28.533+0000] {dagbag.py:588} INFO - Filling up the DagBag from /opt/airflow/dags/eleicao_dag.py
[2024-10-16T11:36:28.651+0000] {logging_mixin.py:190} INFO - [2024-10-16T11:36:28.642+0000] {dagbag.py:387} ERROR - Failed to import: /opt/airflow/dags/eleicao_dag.py
Traceback (most recent call last):
  File "/home/airflow/.local/lib/python3.12/site-packages/airflow/models/dagbag.py", line 383, in parse
    loader.exec_module(new_module)
  File "<frozen importlib._bootstrap_external>", line 995, in exec_module
  File "<frozen importlib._bootstrap>", line 488, in _call_with_frames_removed
  File "/opt/airflow/dags/eleicao_dag.py", line 234, in <module>
    python_callable=process_files,
                    ^^^^^^^^^^^^^
NameError: name 'process_files' is not defined. Did you mean: 'process_log_file'?
[2024-10-16T11:36:28.657+0000] {processor.py:927} WARNING - No viable dags retrieved from /opt/airflow/dags/eleicao_dag.py
[2024-10-16T11:36:28.674+0000] {processor.py:208} INFO - Processing /opt/airflow/dags/eleicao_dag.py took 0.152 seconds
[2024-10-16T11:36:58.930+0000] {processor.py:186} INFO - Started process (PID=126455) to work on /opt/airflow/dags/eleicao_dag.py
[2024-10-16T11:36:58.931+0000] {processor.py:914} INFO - Processing file /opt/airflow/dags/eleicao_dag.py for tasks to queue
[2024-10-16T11:36:58.932+0000] {logging_mixin.py:190} INFO - [2024-10-16T11:36:58.932+0000] {dagbag.py:588} INFO - Filling up the DagBag from /opt/airflow/dags/eleicao_dag.py
[2024-10-16T11:36:59.041+0000] {logging_mixin.py:190} INFO - [2024-10-16T11:36:59.033+0000] {dagbag.py:387} ERROR - Failed to import: /opt/airflow/dags/eleicao_dag.py
Traceback (most recent call last):
  File "/home/airflow/.local/lib/python3.12/site-packages/airflow/models/dagbag.py", line 383, in parse
    loader.exec_module(new_module)
  File "<frozen importlib._bootstrap_external>", line 995, in exec_module
  File "<frozen importlib._bootstrap>", line 488, in _call_with_frames_removed
  File "/opt/airflow/dags/eleicao_dag.py", line 234, in <module>
    python_callable=process_files,
                    ^^^^^^^^^^^^^
NameError: name 'process_files' is not defined. Did you mean: 'process_log_file'?
[2024-10-16T11:36:59.045+0000] {processor.py:927} WARNING - No viable dags retrieved from /opt/airflow/dags/eleicao_dag.py
[2024-10-16T11:36:59.060+0000] {processor.py:208} INFO - Processing /opt/airflow/dags/eleicao_dag.py took 0.136 seconds
[2024-10-16T11:37:29.388+0000] {processor.py:186} INFO - Started process (PID=126518) to work on /opt/airflow/dags/eleicao_dag.py
[2024-10-16T11:37:29.389+0000] {processor.py:914} INFO - Processing file /opt/airflow/dags/eleicao_dag.py for tasks to queue
[2024-10-16T11:37:29.391+0000] {logging_mixin.py:190} INFO - [2024-10-16T11:37:29.390+0000] {dagbag.py:588} INFO - Filling up the DagBag from /opt/airflow/dags/eleicao_dag.py
[2024-10-16T11:37:29.511+0000] {logging_mixin.py:190} INFO - [2024-10-16T11:37:29.500+0000] {dagbag.py:387} ERROR - Failed to import: /opt/airflow/dags/eleicao_dag.py
Traceback (most recent call last):
  File "/home/airflow/.local/lib/python3.12/site-packages/airflow/models/dagbag.py", line 383, in parse
    loader.exec_module(new_module)
  File "<frozen importlib._bootstrap_external>", line 995, in exec_module
  File "<frozen importlib._bootstrap>", line 488, in _call_with_frames_removed
  File "/opt/airflow/dags/eleicao_dag.py", line 234, in <module>
    python_callable=process_files,
                    ^^^^^^^^^^^^^
NameError: name 'process_files' is not defined. Did you mean: 'process_log_file'?
[2024-10-16T11:37:29.516+0000] {processor.py:927} WARNING - No viable dags retrieved from /opt/airflow/dags/eleicao_dag.py
[2024-10-16T11:37:29.530+0000] {processor.py:208} INFO - Processing /opt/airflow/dags/eleicao_dag.py took 0.151 seconds
[2024-10-16T11:38:00.296+0000] {processor.py:186} INFO - Started process (PID=126581) to work on /opt/airflow/dags/eleicao_dag.py
[2024-10-16T11:38:00.298+0000] {processor.py:914} INFO - Processing file /opt/airflow/dags/eleicao_dag.py for tasks to queue
[2024-10-16T11:38:00.299+0000] {logging_mixin.py:190} INFO - [2024-10-16T11:38:00.299+0000] {dagbag.py:588} INFO - Filling up the DagBag from /opt/airflow/dags/eleicao_dag.py
[2024-10-16T11:38:00.424+0000] {logging_mixin.py:190} INFO - [2024-10-16T11:38:00.414+0000] {dagbag.py:387} ERROR - Failed to import: /opt/airflow/dags/eleicao_dag.py
Traceback (most recent call last):
  File "/home/airflow/.local/lib/python3.12/site-packages/airflow/models/dagbag.py", line 383, in parse
    loader.exec_module(new_module)
  File "<frozen importlib._bootstrap_external>", line 995, in exec_module
  File "<frozen importlib._bootstrap>", line 488, in _call_with_frames_removed
  File "/opt/airflow/dags/eleicao_dag.py", line 234, in <module>
    python_callable=process_files,
                    ^^^^^^^^^^^^^
NameError: name 'process_files' is not defined. Did you mean: 'process_log_file'?
[2024-10-16T11:38:00.430+0000] {processor.py:927} WARNING - No viable dags retrieved from /opt/airflow/dags/eleicao_dag.py
[2024-10-16T11:38:00.448+0000] {processor.py:208} INFO - Processing /opt/airflow/dags/eleicao_dag.py took 0.159 seconds
[2024-10-16T11:38:30.982+0000] {processor.py:186} INFO - Started process (PID=126645) to work on /opt/airflow/dags/eleicao_dag.py
[2024-10-16T11:38:30.983+0000] {processor.py:914} INFO - Processing file /opt/airflow/dags/eleicao_dag.py for tasks to queue
[2024-10-16T11:38:30.985+0000] {logging_mixin.py:190} INFO - [2024-10-16T11:38:30.984+0000] {dagbag.py:588} INFO - Filling up the DagBag from /opt/airflow/dags/eleicao_dag.py
[2024-10-16T11:38:31.133+0000] {logging_mixin.py:190} INFO - [2024-10-16T11:38:31.120+0000] {dagbag.py:387} ERROR - Failed to import: /opt/airflow/dags/eleicao_dag.py
Traceback (most recent call last):
  File "/home/airflow/.local/lib/python3.12/site-packages/airflow/models/dagbag.py", line 383, in parse
    loader.exec_module(new_module)
  File "<frozen importlib._bootstrap_external>", line 995, in exec_module
  File "<frozen importlib._bootstrap>", line 488, in _call_with_frames_removed
  File "/opt/airflow/dags/eleicao_dag.py", line 234, in <module>
    python_callable=process_files,
                    ^^^^^^^^^^^^^
NameError: name 'process_files' is not defined. Did you mean: 'process_log_file'?
[2024-10-16T11:38:31.142+0000] {processor.py:927} WARNING - No viable dags retrieved from /opt/airflow/dags/eleicao_dag.py
[2024-10-16T11:38:31.198+0000] {processor.py:208} INFO - Processing /opt/airflow/dags/eleicao_dag.py took 0.223 seconds
[2024-10-16T11:39:02.171+0000] {processor.py:186} INFO - Started process (PID=126708) to work on /opt/airflow/dags/eleicao_dag.py
[2024-10-16T11:39:02.172+0000] {processor.py:914} INFO - Processing file /opt/airflow/dags/eleicao_dag.py for tasks to queue
[2024-10-16T11:39:02.173+0000] {logging_mixin.py:190} INFO - [2024-10-16T11:39:02.173+0000] {dagbag.py:588} INFO - Filling up the DagBag from /opt/airflow/dags/eleicao_dag.py
[2024-10-16T11:39:02.306+0000] {logging_mixin.py:190} INFO - [2024-10-16T11:39:02.296+0000] {dagbag.py:387} ERROR - Failed to import: /opt/airflow/dags/eleicao_dag.py
Traceback (most recent call last):
  File "/home/airflow/.local/lib/python3.12/site-packages/airflow/models/dagbag.py", line 383, in parse
    loader.exec_module(new_module)
  File "<frozen importlib._bootstrap_external>", line 995, in exec_module
  File "<frozen importlib._bootstrap>", line 488, in _call_with_frames_removed
  File "/opt/airflow/dags/eleicao_dag.py", line 234, in <module>
    python_callable=process_files,
                    ^^^^^^^^^^^^^
NameError: name 'process_files' is not defined. Did you mean: 'process_log_file'?
[2024-10-16T11:39:02.312+0000] {processor.py:927} WARNING - No viable dags retrieved from /opt/airflow/dags/eleicao_dag.py
[2024-10-16T11:39:02.331+0000] {processor.py:208} INFO - Processing /opt/airflow/dags/eleicao_dag.py took 0.167 seconds
[2024-10-16T11:39:33.029+0000] {processor.py:186} INFO - Started process (PID=126771) to work on /opt/airflow/dags/eleicao_dag.py
[2024-10-16T11:39:33.030+0000] {processor.py:914} INFO - Processing file /opt/airflow/dags/eleicao_dag.py for tasks to queue
[2024-10-16T11:39:33.031+0000] {logging_mixin.py:190} INFO - [2024-10-16T11:39:33.031+0000] {dagbag.py:588} INFO - Filling up the DagBag from /opt/airflow/dags/eleicao_dag.py
[2024-10-16T11:39:33.156+0000] {logging_mixin.py:190} INFO - [2024-10-16T11:39:33.147+0000] {dagbag.py:387} ERROR - Failed to import: /opt/airflow/dags/eleicao_dag.py
Traceback (most recent call last):
  File "/home/airflow/.local/lib/python3.12/site-packages/airflow/models/dagbag.py", line 383, in parse
    loader.exec_module(new_module)
  File "<frozen importlib._bootstrap_external>", line 995, in exec_module
  File "<frozen importlib._bootstrap>", line 488, in _call_with_frames_removed
  File "/opt/airflow/dags/eleicao_dag.py", line 234, in <module>
    python_callable=process_files,
                    ^^^^^^^^^^^^^
NameError: name 'process_files' is not defined. Did you mean: 'process_log_file'?
[2024-10-16T11:39:33.162+0000] {processor.py:927} WARNING - No viable dags retrieved from /opt/airflow/dags/eleicao_dag.py
[2024-10-16T11:39:33.181+0000] {processor.py:208} INFO - Processing /opt/airflow/dags/eleicao_dag.py took 0.159 seconds
[2024-10-16T11:40:03.786+0000] {processor.py:186} INFO - Started process (PID=126834) to work on /opt/airflow/dags/eleicao_dag.py
[2024-10-16T11:40:03.787+0000] {processor.py:914} INFO - Processing file /opt/airflow/dags/eleicao_dag.py for tasks to queue
[2024-10-16T11:40:03.789+0000] {logging_mixin.py:190} INFO - [2024-10-16T11:40:03.788+0000] {dagbag.py:588} INFO - Filling up the DagBag from /opt/airflow/dags/eleicao_dag.py
[2024-10-16T11:40:03.915+0000] {logging_mixin.py:190} INFO - [2024-10-16T11:40:03.906+0000] {dagbag.py:387} ERROR - Failed to import: /opt/airflow/dags/eleicao_dag.py
Traceback (most recent call last):
  File "/home/airflow/.local/lib/python3.12/site-packages/airflow/models/dagbag.py", line 383, in parse
    loader.exec_module(new_module)
  File "<frozen importlib._bootstrap_external>", line 995, in exec_module
  File "<frozen importlib._bootstrap>", line 488, in _call_with_frames_removed
  File "/opt/airflow/dags/eleicao_dag.py", line 234, in <module>
    python_callable=process_files,
                    ^^^^^^^^^^^^^
NameError: name 'process_files' is not defined. Did you mean: 'process_log_file'?
[2024-10-16T11:40:03.920+0000] {processor.py:927} WARNING - No viable dags retrieved from /opt/airflow/dags/eleicao_dag.py
[2024-10-16T11:40:03.938+0000] {processor.py:208} INFO - Processing /opt/airflow/dags/eleicao_dag.py took 0.159 seconds
[2024-10-16T11:40:34.000+0000] {processor.py:186} INFO - Started process (PID=126896) to work on /opt/airflow/dags/eleicao_dag.py
[2024-10-16T11:40:34.001+0000] {processor.py:914} INFO - Processing file /opt/airflow/dags/eleicao_dag.py for tasks to queue
[2024-10-16T11:40:34.003+0000] {logging_mixin.py:190} INFO - [2024-10-16T11:40:34.002+0000] {dagbag.py:588} INFO - Filling up the DagBag from /opt/airflow/dags/eleicao_dag.py
[2024-10-16T11:40:34.138+0000] {logging_mixin.py:190} INFO - [2024-10-16T11:40:34.129+0000] {dagbag.py:387} ERROR - Failed to import: /opt/airflow/dags/eleicao_dag.py
Traceback (most recent call last):
  File "/home/airflow/.local/lib/python3.12/site-packages/airflow/models/dagbag.py", line 383, in parse
    loader.exec_module(new_module)
  File "<frozen importlib._bootstrap_external>", line 995, in exec_module
  File "<frozen importlib._bootstrap>", line 488, in _call_with_frames_removed
  File "/opt/airflow/dags/eleicao_dag.py", line 234, in <module>
    python_callable=process_files,
                    ^^^^^^^^^^^^^
NameError: name 'process_files' is not defined. Did you mean: 'process_log_file'?
[2024-10-16T11:40:34.144+0000] {processor.py:927} WARNING - No viable dags retrieved from /opt/airflow/dags/eleicao_dag.py
[2024-10-16T11:40:34.163+0000] {processor.py:208} INFO - Processing /opt/airflow/dags/eleicao_dag.py took 0.169 seconds
[2024-10-16T11:41:04.264+0000] {processor.py:186} INFO - Started process (PID=126959) to work on /opt/airflow/dags/eleicao_dag.py
[2024-10-16T11:41:04.265+0000] {processor.py:914} INFO - Processing file /opt/airflow/dags/eleicao_dag.py for tasks to queue
[2024-10-16T11:41:04.266+0000] {logging_mixin.py:190} INFO - [2024-10-16T11:41:04.266+0000] {dagbag.py:588} INFO - Filling up the DagBag from /opt/airflow/dags/eleicao_dag.py
[2024-10-16T11:41:04.402+0000] {logging_mixin.py:190} INFO - [2024-10-16T11:41:04.393+0000] {dagbag.py:387} ERROR - Failed to import: /opt/airflow/dags/eleicao_dag.py
Traceback (most recent call last):
  File "/home/airflow/.local/lib/python3.12/site-packages/airflow/models/dagbag.py", line 383, in parse
    loader.exec_module(new_module)
  File "<frozen importlib._bootstrap_external>", line 995, in exec_module
  File "<frozen importlib._bootstrap>", line 488, in _call_with_frames_removed
  File "/opt/airflow/dags/eleicao_dag.py", line 234, in <module>
    python_callable=process_files,
                    ^^^^^^^^^^^^^
NameError: name 'process_files' is not defined. Did you mean: 'process_log_file'?
[2024-10-16T11:41:04.408+0000] {processor.py:927} WARNING - No viable dags retrieved from /opt/airflow/dags/eleicao_dag.py
[2024-10-16T11:41:04.426+0000] {processor.py:208} INFO - Processing /opt/airflow/dags/eleicao_dag.py took 0.169 seconds
[2024-10-16T11:41:34.673+0000] {processor.py:186} INFO - Started process (PID=127022) to work on /opt/airflow/dags/eleicao_dag.py
[2024-10-16T11:41:34.675+0000] {processor.py:914} INFO - Processing file /opt/airflow/dags/eleicao_dag.py for tasks to queue
[2024-10-16T11:41:34.676+0000] {logging_mixin.py:190} INFO - [2024-10-16T11:41:34.676+0000] {dagbag.py:588} INFO - Filling up the DagBag from /opt/airflow/dags/eleicao_dag.py
[2024-10-16T11:41:34.804+0000] {logging_mixin.py:190} INFO - [2024-10-16T11:41:34.795+0000] {dagbag.py:387} ERROR - Failed to import: /opt/airflow/dags/eleicao_dag.py
Traceback (most recent call last):
  File "/home/airflow/.local/lib/python3.12/site-packages/airflow/models/dagbag.py", line 383, in parse
    loader.exec_module(new_module)
  File "<frozen importlib._bootstrap_external>", line 995, in exec_module
  File "<frozen importlib._bootstrap>", line 488, in _call_with_frames_removed
  File "/opt/airflow/dags/eleicao_dag.py", line 234, in <module>
    python_callable=process_files,
                    ^^^^^^^^^^^^^
NameError: name 'process_files' is not defined. Did you mean: 'process_log_file'?
[2024-10-16T11:41:34.809+0000] {processor.py:927} WARNING - No viable dags retrieved from /opt/airflow/dags/eleicao_dag.py
[2024-10-16T11:41:34.827+0000] {processor.py:208} INFO - Processing /opt/airflow/dags/eleicao_dag.py took 0.161 seconds
[2024-10-16T11:42:05.474+0000] {processor.py:186} INFO - Started process (PID=127085) to work on /opt/airflow/dags/eleicao_dag.py
[2024-10-16T11:42:05.475+0000] {processor.py:914} INFO - Processing file /opt/airflow/dags/eleicao_dag.py for tasks to queue
[2024-10-16T11:42:05.477+0000] {logging_mixin.py:190} INFO - [2024-10-16T11:42:05.476+0000] {dagbag.py:588} INFO - Filling up the DagBag from /opt/airflow/dags/eleicao_dag.py
[2024-10-16T11:42:05.603+0000] {logging_mixin.py:190} INFO - [2024-10-16T11:42:05.594+0000] {dagbag.py:387} ERROR - Failed to import: /opt/airflow/dags/eleicao_dag.py
Traceback (most recent call last):
  File "/home/airflow/.local/lib/python3.12/site-packages/airflow/models/dagbag.py", line 383, in parse
    loader.exec_module(new_module)
  File "<frozen importlib._bootstrap_external>", line 995, in exec_module
  File "<frozen importlib._bootstrap>", line 488, in _call_with_frames_removed
  File "/opt/airflow/dags/eleicao_dag.py", line 234, in <module>
    python_callable=process_files,
                    ^^^^^^^^^^^^^
NameError: name 'process_files' is not defined. Did you mean: 'process_log_file'?
[2024-10-16T11:42:05.609+0000] {processor.py:927} WARNING - No viable dags retrieved from /opt/airflow/dags/eleicao_dag.py
[2024-10-16T11:42:05.628+0000] {processor.py:208} INFO - Processing /opt/airflow/dags/eleicao_dag.py took 0.161 seconds
[2024-10-16T11:42:35.749+0000] {processor.py:186} INFO - Started process (PID=127148) to work on /opt/airflow/dags/eleicao_dag.py
[2024-10-16T11:42:35.750+0000] {processor.py:914} INFO - Processing file /opt/airflow/dags/eleicao_dag.py for tasks to queue
[2024-10-16T11:42:35.752+0000] {logging_mixin.py:190} INFO - [2024-10-16T11:42:35.751+0000] {dagbag.py:588} INFO - Filling up the DagBag from /opt/airflow/dags/eleicao_dag.py
[2024-10-16T11:42:35.879+0000] {logging_mixin.py:190} INFO - [2024-10-16T11:42:35.869+0000] {dagbag.py:387} ERROR - Failed to import: /opt/airflow/dags/eleicao_dag.py
Traceback (most recent call last):
  File "/home/airflow/.local/lib/python3.12/site-packages/airflow/models/dagbag.py", line 383, in parse
    loader.exec_module(new_module)
  File "<frozen importlib._bootstrap_external>", line 995, in exec_module
  File "<frozen importlib._bootstrap>", line 488, in _call_with_frames_removed
  File "/opt/airflow/dags/eleicao_dag.py", line 234, in <module>
    python_callable=process_files,
                    ^^^^^^^^^^^^^
NameError: name 'process_files' is not defined. Did you mean: 'process_log_file'?
[2024-10-16T11:42:35.887+0000] {processor.py:927} WARNING - No viable dags retrieved from /opt/airflow/dags/eleicao_dag.py
[2024-10-16T11:42:35.909+0000] {processor.py:208} INFO - Processing /opt/airflow/dags/eleicao_dag.py took 0.166 seconds
[2024-10-16T11:43:06.607+0000] {processor.py:186} INFO - Started process (PID=127211) to work on /opt/airflow/dags/eleicao_dag.py
[2024-10-16T11:43:06.608+0000] {processor.py:914} INFO - Processing file /opt/airflow/dags/eleicao_dag.py for tasks to queue
[2024-10-16T11:43:06.609+0000] {logging_mixin.py:190} INFO - [2024-10-16T11:43:06.609+0000] {dagbag.py:588} INFO - Filling up the DagBag from /opt/airflow/dags/eleicao_dag.py
[2024-10-16T11:43:06.735+0000] {logging_mixin.py:190} INFO - [2024-10-16T11:43:06.726+0000] {dagbag.py:387} ERROR - Failed to import: /opt/airflow/dags/eleicao_dag.py
Traceback (most recent call last):
  File "/home/airflow/.local/lib/python3.12/site-packages/airflow/models/dagbag.py", line 383, in parse
    loader.exec_module(new_module)
  File "<frozen importlib._bootstrap_external>", line 995, in exec_module
  File "<frozen importlib._bootstrap>", line 488, in _call_with_frames_removed
  File "/opt/airflow/dags/eleicao_dag.py", line 234, in <module>
    python_callable=process_files,
                    ^^^^^^^^^^^^^
NameError: name 'process_files' is not defined. Did you mean: 'process_log_file'?
[2024-10-16T11:43:06.740+0000] {processor.py:927} WARNING - No viable dags retrieved from /opt/airflow/dags/eleicao_dag.py
[2024-10-16T11:43:06.759+0000] {processor.py:208} INFO - Processing /opt/airflow/dags/eleicao_dag.py took 0.159 seconds
[2024-10-16T11:43:36.861+0000] {processor.py:186} INFO - Started process (PID=127275) to work on /opt/airflow/dags/eleicao_dag.py
[2024-10-16T11:43:36.863+0000] {processor.py:914} INFO - Processing file /opt/airflow/dags/eleicao_dag.py for tasks to queue
[2024-10-16T11:43:36.864+0000] {logging_mixin.py:190} INFO - [2024-10-16T11:43:36.864+0000] {dagbag.py:588} INFO - Filling up the DagBag from /opt/airflow/dags/eleicao_dag.py
[2024-10-16T11:43:36.996+0000] {logging_mixin.py:190} INFO - [2024-10-16T11:43:36.986+0000] {dagbag.py:387} ERROR - Failed to import: /opt/airflow/dags/eleicao_dag.py
Traceback (most recent call last):
  File "/home/airflow/.local/lib/python3.12/site-packages/airflow/models/dagbag.py", line 383, in parse
    loader.exec_module(new_module)
  File "<frozen importlib._bootstrap_external>", line 995, in exec_module
  File "<frozen importlib._bootstrap>", line 488, in _call_with_frames_removed
  File "/opt/airflow/dags/eleicao_dag.py", line 234, in <module>
    python_callable=process_files,
                    ^^^^^^^^^^^^^
NameError: name 'process_files' is not defined. Did you mean: 'process_log_file'?
[2024-10-16T11:43:37.002+0000] {processor.py:927} WARNING - No viable dags retrieved from /opt/airflow/dags/eleicao_dag.py
[2024-10-16T11:43:37.021+0000] {processor.py:208} INFO - Processing /opt/airflow/dags/eleicao_dag.py took 0.167 seconds
[2024-10-16T11:44:07.092+0000] {processor.py:186} INFO - Started process (PID=127338) to work on /opt/airflow/dags/eleicao_dag.py
[2024-10-16T11:44:07.094+0000] {processor.py:914} INFO - Processing file /opt/airflow/dags/eleicao_dag.py for tasks to queue
[2024-10-16T11:44:07.096+0000] {logging_mixin.py:190} INFO - [2024-10-16T11:44:07.096+0000] {dagbag.py:588} INFO - Filling up the DagBag from /opt/airflow/dags/eleicao_dag.py
[2024-10-16T11:44:07.236+0000] {logging_mixin.py:190} INFO - [2024-10-16T11:44:07.225+0000] {dagbag.py:387} ERROR - Failed to import: /opt/airflow/dags/eleicao_dag.py
Traceback (most recent call last):
  File "/home/airflow/.local/lib/python3.12/site-packages/airflow/models/dagbag.py", line 383, in parse
    loader.exec_module(new_module)
  File "<frozen importlib._bootstrap_external>", line 995, in exec_module
  File "<frozen importlib._bootstrap>", line 488, in _call_with_frames_removed
  File "/opt/airflow/dags/eleicao_dag.py", line 234, in <module>
    python_callable=process_files,
                    ^^^^^^^^^^^^^
NameError: name 'process_files' is not defined. Did you mean: 'process_log_file'?
[2024-10-16T11:44:07.242+0000] {processor.py:927} WARNING - No viable dags retrieved from /opt/airflow/dags/eleicao_dag.py
[2024-10-16T11:44:07.260+0000] {processor.py:208} INFO - Processing /opt/airflow/dags/eleicao_dag.py took 0.174 seconds
[2024-10-16T11:44:37.765+0000] {processor.py:186} INFO - Started process (PID=127401) to work on /opt/airflow/dags/eleicao_dag.py
[2024-10-16T11:44:37.766+0000] {processor.py:914} INFO - Processing file /opt/airflow/dags/eleicao_dag.py for tasks to queue
[2024-10-16T11:44:37.767+0000] {logging_mixin.py:190} INFO - [2024-10-16T11:44:37.767+0000] {dagbag.py:588} INFO - Filling up the DagBag from /opt/airflow/dags/eleicao_dag.py
[2024-10-16T11:44:37.897+0000] {logging_mixin.py:190} INFO - [2024-10-16T11:44:37.888+0000] {dagbag.py:387} ERROR - Failed to import: /opt/airflow/dags/eleicao_dag.py
Traceback (most recent call last):
  File "/home/airflow/.local/lib/python3.12/site-packages/airflow/models/dagbag.py", line 383, in parse
    loader.exec_module(new_module)
  File "<frozen importlib._bootstrap_external>", line 995, in exec_module
  File "<frozen importlib._bootstrap>", line 488, in _call_with_frames_removed
  File "/opt/airflow/dags/eleicao_dag.py", line 234, in <module>
    python_callable=process_files,
                    ^^^^^^^^^^^^^
NameError: name 'process_files' is not defined. Did you mean: 'process_log_file'?
[2024-10-16T11:44:37.903+0000] {processor.py:927} WARNING - No viable dags retrieved from /opt/airflow/dags/eleicao_dag.py
[2024-10-16T11:44:37.922+0000] {processor.py:208} INFO - Processing /opt/airflow/dags/eleicao_dag.py took 0.164 seconds
[2024-10-16T11:45:08.042+0000] {processor.py:186} INFO - Started process (PID=127464) to work on /opt/airflow/dags/eleicao_dag.py
[2024-10-16T11:45:08.043+0000] {processor.py:914} INFO - Processing file /opt/airflow/dags/eleicao_dag.py for tasks to queue
[2024-10-16T11:45:08.045+0000] {logging_mixin.py:190} INFO - [2024-10-16T11:45:08.044+0000] {dagbag.py:588} INFO - Filling up the DagBag from /opt/airflow/dags/eleicao_dag.py
[2024-10-16T11:45:08.170+0000] {logging_mixin.py:190} INFO - [2024-10-16T11:45:08.161+0000] {dagbag.py:387} ERROR - Failed to import: /opt/airflow/dags/eleicao_dag.py
Traceback (most recent call last):
  File "/home/airflow/.local/lib/python3.12/site-packages/airflow/models/dagbag.py", line 383, in parse
    loader.exec_module(new_module)
  File "<frozen importlib._bootstrap_external>", line 995, in exec_module
  File "<frozen importlib._bootstrap>", line 488, in _call_with_frames_removed
  File "/opt/airflow/dags/eleicao_dag.py", line 234, in <module>
    python_callable=process_files,
                    ^^^^^^^^^^^^^
NameError: name 'process_files' is not defined. Did you mean: 'process_log_file'?
[2024-10-16T11:45:08.177+0000] {processor.py:927} WARNING - No viable dags retrieved from /opt/airflow/dags/eleicao_dag.py
[2024-10-16T11:45:08.199+0000] {processor.py:208} INFO - Processing /opt/airflow/dags/eleicao_dag.py took 0.163 seconds
[2024-10-16T11:45:38.404+0000] {processor.py:186} INFO - Started process (PID=127527) to work on /opt/airflow/dags/eleicao_dag.py
[2024-10-16T11:45:38.405+0000] {processor.py:914} INFO - Processing file /opt/airflow/dags/eleicao_dag.py for tasks to queue
[2024-10-16T11:45:38.407+0000] {logging_mixin.py:190} INFO - [2024-10-16T11:45:38.406+0000] {dagbag.py:588} INFO - Filling up the DagBag from /opt/airflow/dags/eleicao_dag.py
[2024-10-16T11:45:38.550+0000] {logging_mixin.py:190} INFO - [2024-10-16T11:45:38.541+0000] {dagbag.py:387} ERROR - Failed to import: /opt/airflow/dags/eleicao_dag.py
Traceback (most recent call last):
  File "/home/airflow/.local/lib/python3.12/site-packages/airflow/models/dagbag.py", line 383, in parse
    loader.exec_module(new_module)
  File "<frozen importlib._bootstrap_external>", line 995, in exec_module
  File "<frozen importlib._bootstrap>", line 488, in _call_with_frames_removed
  File "/opt/airflow/dags/eleicao_dag.py", line 234, in <module>
    python_callable=process_files,
                    ^^^^^^^^^^^^^
NameError: name 'process_files' is not defined. Did you mean: 'process_log_file'?
[2024-10-16T11:45:38.557+0000] {processor.py:927} WARNING - No viable dags retrieved from /opt/airflow/dags/eleicao_dag.py
[2024-10-16T11:45:38.582+0000] {processor.py:208} INFO - Processing /opt/airflow/dags/eleicao_dag.py took 0.189 seconds
