[2024-10-11T18:52:50.383+0000] {local_task_job_runner.py:123} INFO - ::group::Pre task execution logs
[2024-10-11T18:52:50.398+0000] {taskinstance.py:2612} INFO - Dependencies all met for dep_context=non-requeueable deps ti=<TaskInstance: pipeline_urna_eleitoral.download_file scheduled__2024-10-10T00:00:00+00:00 [queued]>
[2024-10-11T18:52:50.404+0000] {taskinstance.py:2612} INFO - Dependencies all met for dep_context=requeueable deps ti=<TaskInstance: pipeline_urna_eleitoral.download_file scheduled__2024-10-10T00:00:00+00:00 [queued]>
[2024-10-11T18:52:50.405+0000] {taskinstance.py:2865} INFO - Starting attempt 1 of 2
[2024-10-11T18:52:50.418+0000] {taskinstance.py:2888} INFO - Executing <Task(PythonOperator): download_file> on 2024-10-10 00:00:00+00:00
[2024-10-11T18:52:50.425+0000] {warnings.py:112} WARNING - /home/***/.local/lib/python3.12/site-packages/***/task/task_runner/standard_task_runner.py:70: DeprecationWarning: This process (pid=181) is multi-threaded, use of fork() may lead to deadlocks in the child.
  pid = os.fork()

[2024-10-11T18:52:50.426+0000] {standard_task_runner.py:72} INFO - Started process 183 to run task
[2024-10-11T18:52:50.427+0000] {standard_task_runner.py:104} INFO - Running: ['***', 'tasks', 'run', 'pipeline_urna_eleitoral', 'download_file', 'scheduled__2024-10-10T00:00:00+00:00', '--job-id', '5', '--raw', '--subdir', 'DAGS_FOLDER/eleicao_dag.py', '--cfg-path', '/tmp/tmp2b8egg__']
[2024-10-11T18:52:50.428+0000] {standard_task_runner.py:105} INFO - Job 5: Subtask download_file
[2024-10-11T18:52:50.493+0000] {task_command.py:467} INFO - Running <TaskInstance: pipeline_urna_eleitoral.download_file scheduled__2024-10-10T00:00:00+00:00 [running]> on host b314392f40ca
[2024-10-11T18:52:50.620+0000] {taskinstance.py:3131} INFO - Exporting env vars: AIRFLOW_CTX_DAG_OWNER='***' AIRFLOW_CTX_DAG_ID='pipeline_urna_eleitoral' AIRFLOW_CTX_TASK_ID='download_file' AIRFLOW_CTX_EXECUTION_DATE='2024-10-10T00:00:00+00:00' AIRFLOW_CTX_TRY_NUMBER='1' AIRFLOW_CTX_DAG_RUN_ID='scheduled__2024-10-10T00:00:00+00:00'
[2024-10-11T18:52:50.627+0000] {logging_mixin.py:190} INFO - Task instance is in running state
[2024-10-11T18:52:50.628+0000] {logging_mixin.py:190} INFO -  Previous state of the Task instance: queued
[2024-10-11T18:52:50.628+0000] {logging_mixin.py:190} INFO - Current task name:download_file state:running start_date:2024-10-11 18:52:50.399420+00:00
[2024-10-11T18:52:50.629+0000] {logging_mixin.py:190} INFO - Dag name:pipeline_urna_eleitoral and current dag run status:running
[2024-10-11T18:52:50.629+0000] {taskinstance.py:731} INFO - ::endgroup::
[2024-10-11T18:52:53.122+0000] {taskinstance.py:3310} ERROR - Task failed with exception
Traceback (most recent call last):
  File "/home/airflow/.local/lib/python3.12/site-packages/airflow/models/taskinstance.py", line 767, in _execute_task
    result = _execute_callable(context=context, **execute_callable_kwargs)
             ^^^^^^^^^^^^^^^^^^^^^^^^^^^^^^^^^^^^^^^^^^^^^^^^^^^^^^^^^^^^^
  File "/home/airflow/.local/lib/python3.12/site-packages/airflow/models/taskinstance.py", line 733, in _execute_callable
    return ExecutionCallableRunner(
           ^^^^^^^^^^^^^^^^^^^^^^^^
  File "/home/airflow/.local/lib/python3.12/site-packages/airflow/utils/operator_helpers.py", line 252, in run
    return self.func(*args, **kwargs)
           ^^^^^^^^^^^^^^^^^^^^^^^^^^
  File "/home/airflow/.local/lib/python3.12/site-packages/airflow/models/baseoperator.py", line 406, in wrapper
    return func(self, *args, **kwargs)
           ^^^^^^^^^^^^^^^^^^^^^^^^^^^
  File "/home/airflow/.local/lib/python3.12/site-packages/airflow/operators/python.py", line 238, in execute
    return_value = self.execute_callable()
                   ^^^^^^^^^^^^^^^^^^^^^^^
  File "/home/airflow/.local/lib/python3.12/site-packages/airflow/operators/python.py", line 256, in execute_callable
    return runner.run(*self.op_args, **self.op_kwargs)
           ^^^^^^^^^^^^^^^^^^^^^^^^^^^^^^^^^^^^^^^^^^^
  File "/home/airflow/.local/lib/python3.12/site-packages/airflow/utils/operator_helpers.py", line 252, in run
    return self.func(*args, **kwargs)
           ^^^^^^^^^^^^^^^^^^^^^^^^^^
  File "/opt/airflow/dags/eleicao_dag.py", line 13, in download_file
    with open(output_path, 'wb') as f:
         ^^^^^^^^^^^^^^^^^^^^^^^
FileNotFoundError: [Errno 2] No such file or directory: '/path_para_salvar_arquivo/arquivo_urna.zip'
[2024-10-11T18:52:53.139+0000] {logging_mixin.py:190} INFO - Task instance in failure state
[2024-10-11T18:52:53.139+0000] {logging_mixin.py:190} INFO - Task start:2024-10-11 18:52:50.399420+00:00 end:2024-10-11 18:52:53.138414+00:00 duration:2.738994
[2024-10-11T18:52:53.140+0000] {logging_mixin.py:190} INFO - Task:<Task(PythonOperator): download_file> dag:<DAG: pipeline_urna_eleitoral> dagrun:<DagRun pipeline_urna_eleitoral @ 2024-10-10 00:00:00+00:00: scheduled__2024-10-10T00:00:00+00:00, state:running, queued_at: 2024-10-11 18:52:46.217712+00:00. externally triggered: False>
[2024-10-11T18:52:53.140+0000] {logging_mixin.py:190} INFO - Failure caused by [Errno 2] No such file or directory: '/path_para_salvar_arquivo/arquivo_urna.zip'
[2024-10-11T18:52:53.141+0000] {taskinstance.py:1225} INFO - Marking task as UP_FOR_RETRY. dag_id=pipeline_urna_eleitoral, task_id=download_file, run_id=scheduled__2024-10-10T00:00:00+00:00, execution_date=20241010T000000, start_date=20241011T185250, end_date=20241011T185253
[2024-10-11T18:52:53.159+0000] {taskinstance.py:340} INFO - ::group::Post task execution logs
[2024-10-11T18:52:53.160+0000] {standard_task_runner.py:124} ERROR - Failed to execute job 5 for task download_file ([Errno 2] No such file or directory: '/path_para_salvar_arquivo/arquivo_urna.zip'; 183)
Traceback (most recent call last):
  File "/home/airflow/.local/lib/python3.12/site-packages/airflow/task/task_runner/standard_task_runner.py", line 117, in _start_by_fork
    ret = args.func(args, dag=self.dag)
          ^^^^^^^^^^^^^^^^^^^^^^^^^^^^^
  File "/home/airflow/.local/lib/python3.12/site-packages/airflow/cli/cli_config.py", line 49, in command
    return func(*args, **kwargs)
           ^^^^^^^^^^^^^^^^^^^^^
  File "/home/airflow/.local/lib/python3.12/site-packages/airflow/utils/cli.py", line 115, in wrapper
    return f(*args, **kwargs)
           ^^^^^^^^^^^^^^^^^^
  File "/home/airflow/.local/lib/python3.12/site-packages/airflow/cli/commands/task_command.py", line 483, in task_run
    task_return_code = _run_task_by_selected_method(args, _dag, ti)
                       ^^^^^^^^^^^^^^^^^^^^^^^^^^^^^^^^^^^^^^^^^^^^
  File "/home/airflow/.local/lib/python3.12/site-packages/airflow/cli/commands/task_command.py", line 256, in _run_task_by_selected_method
    return _run_raw_task(args, ti)
           ^^^^^^^^^^^^^^^^^^^^^^^
  File "/home/airflow/.local/lib/python3.12/site-packages/airflow/cli/commands/task_command.py", line 341, in _run_raw_task
    return ti._run_raw_task(
           ^^^^^^^^^^^^^^^^^
  File "/home/airflow/.local/lib/python3.12/site-packages/airflow/utils/session.py", line 97, in wrapper
    return func(*args, session=session, **kwargs)
           ^^^^^^^^^^^^^^^^^^^^^^^^^^^^^^^^^^^^^^
  File "/home/airflow/.local/lib/python3.12/site-packages/airflow/models/taskinstance.py", line 3004, in _run_raw_task
    return _run_raw_task(
           ^^^^^^^^^^^^^^
  File "/home/airflow/.local/lib/python3.12/site-packages/airflow/models/taskinstance.py", line 273, in _run_raw_task
    TaskInstance._execute_task_with_callbacks(
  File "/home/airflow/.local/lib/python3.12/site-packages/airflow/models/taskinstance.py", line 3158, in _execute_task_with_callbacks
    result = self._execute_task(context, task_orig)
             ^^^^^^^^^^^^^^^^^^^^^^^^^^^^^^^^^^^^^^
  File "/home/airflow/.local/lib/python3.12/site-packages/airflow/models/taskinstance.py", line 3182, in _execute_task
    return _execute_task(self, context, task_orig)
           ^^^^^^^^^^^^^^^^^^^^^^^^^^^^^^^^^^^^^^^
  File "/home/airflow/.local/lib/python3.12/site-packages/airflow/models/taskinstance.py", line 767, in _execute_task
    result = _execute_callable(context=context, **execute_callable_kwargs)
             ^^^^^^^^^^^^^^^^^^^^^^^^^^^^^^^^^^^^^^^^^^^^^^^^^^^^^^^^^^^^^
  File "/home/airflow/.local/lib/python3.12/site-packages/airflow/models/taskinstance.py", line 733, in _execute_callable
    return ExecutionCallableRunner(
           ^^^^^^^^^^^^^^^^^^^^^^^^
  File "/home/airflow/.local/lib/python3.12/site-packages/airflow/utils/operator_helpers.py", line 252, in run
    return self.func(*args, **kwargs)
           ^^^^^^^^^^^^^^^^^^^^^^^^^^
  File "/home/airflow/.local/lib/python3.12/site-packages/airflow/models/baseoperator.py", line 406, in wrapper
    return func(self, *args, **kwargs)
           ^^^^^^^^^^^^^^^^^^^^^^^^^^^
  File "/home/airflow/.local/lib/python3.12/site-packages/airflow/operators/python.py", line 238, in execute
    return_value = self.execute_callable()
                   ^^^^^^^^^^^^^^^^^^^^^^^
  File "/home/airflow/.local/lib/python3.12/site-packages/airflow/operators/python.py", line 256, in execute_callable
    return runner.run(*self.op_args, **self.op_kwargs)
           ^^^^^^^^^^^^^^^^^^^^^^^^^^^^^^^^^^^^^^^^^^^
  File "/home/airflow/.local/lib/python3.12/site-packages/airflow/utils/operator_helpers.py", line 252, in run
    return self.func(*args, **kwargs)
           ^^^^^^^^^^^^^^^^^^^^^^^^^^
  File "/opt/airflow/dags/eleicao_dag.py", line 13, in download_file
    with open(output_path, 'wb') as f:
         ^^^^^^^^^^^^^^^^^^^^^^^
FileNotFoundError: [Errno 2] No such file or directory: '/path_para_salvar_arquivo/arquivo_urna.zip'
[2024-10-11T18:52:53.173+0000] {local_task_job_runner.py:266} INFO - Task exited with return code 1
[2024-10-11T18:52:53.192+0000] {taskinstance.py:3900} INFO - 0 downstream tasks scheduled from follow-on schedule check
[2024-10-11T18:52:53.195+0000] {local_task_job_runner.py:245} INFO - ::endgroup::
